<?xml version="1.0" encoding="utf-8"?>
<!-- This URDF was automatically created by SolidWorks to URDF Exporter! Originally created by Stephen Brawner (brawner@gmail.com) 
     Commit Version: 1.6.0-1-g15f4949  Build Version: 1.6.7594.29634
     For more information, please see http://wiki.ros.org/sw_urdf_exporter -->
<robot
  name="Assem3">
  <link
    name="base_link">
    <inertial>
      <origin
        xyz="2.91765925455794E-18 0.034171777162118 -3.43860953728826E-19"
        rpy="0 0 0" />
      <mass
        value="0.469704823210628" />
      <inertia
        ixx="0.00196091760537738"
        ixy="-9.06133927341335E-21"
        ixz="3.73016778970376E-21"
        iyy="0.00243238074407107"
        iyz="5.94629839607918E-22"
        izz="0.00236051675686462" />
    </inertial>
    <visual>
      <origin
        xyz="0 0 0"
        rpy="0 0 0" />
      <geometry>
        <mesh
          filename="package://Assem3/meshes/base_link.STL" />
      </geometry>
      <material
        name="">
        <color
          rgba="0.792156862745098 0.819607843137255 0.933333333333333 1" />
      </material>
    </visual>
    <collision>
      <origin
        xyz="0 0 0"
        rpy="0 0 0" />
      <geometry>
        <mesh
          filename="package://Assem3/meshes/base_link.STL" />
      </geometry>
    </collision>
  </link>
  <link
    name="link1">
    <inertial>
      <origin
        xyz="-0.0192276021278841 0.144752844839244 0.000150744051583183"
        rpy="0 0 0" />
      <mass
        value="0.873842928539536" />
      <inertia
        ixx="0.0038152636726692"
        ixy="0.000233341990302269"
        ixz="-4.66438512714831E-06"
        iyy="0.00230822990422381"
        iyz="6.96241608786371E-09"
        izz="0.004544987645007" />
    </inertial>
    <visual>
      <origin
        xyz="0 0 0"
        rpy="0 0 0" />
      <geometry>
        <mesh
          filename="package://Assem3/meshes/link1.STL" />
      </geometry>
      <material
        name="">
        <color
          rgba="0.792156862745098 0.819607843137255 0.933333333333333 1" />
      </material>
    </visual>
    <collision>
      <origin
        xyz="0 0 0"
        rpy="0 0 0" />
      <geometry>
        <mesh
          filename="package://Assem3/meshes/link1.STL" />
      </geometry>
    </collision>
  </link>
  <joint
    name="base_link_link1"
    type="revolute">
    <origin
      xyz="0 0 0.025"
      rpy="1.5708 0 0.43037" />
    <parent
      link="base_link" />
    <child
      link="link1" />
    <axis
      xyz="0 1 0" />
    <limit
      lower="-1.57"
      upper="1.57"
      effort="10"
      velocity="10" />
  </joint>
  <link
    name="link2">
    <inertial>
      <origin
        xyz="-0.083959 0.1324 -2.4672E-07"
        rpy="0 0 0" />
      <mass
        value="0.5121" />
      <inertia
        ixx="0.00028663"
        ixy="7.5433E-06"
        ixz="-2.8242E-10"
        iyy="0.0011784"
        iyz="-5.6328E-20"
        izz="0.0012928" />
    </inertial>
    <visual>
      <origin
        xyz="0 0 0"
        rpy="0 0 0" />
      <geometry>
        <mesh
          filename="package://Assem3/meshes/link2.STL" />
      </geometry>
      <material
        name="">
        <color
          rgba="0.79216 0.81961 0.93333 1" />
      </material>
    </visual>
    <collision>
      <origin
        xyz="0 0 0"
        rpy="0 0 0" />
      <geometry>
        <mesh
          filename="package://Assem3/meshes/link2.STL" />
      </geometry>
    </collision>
  </link>
  <joint
    name="link1_link2"
    type="prismatic">
    <origin
      xyz="0 -0.019 0"
      rpy="0 0 0" />
    <parent
      link="link1" />
    <child
      link="link2" />
    <axis
      xyz="0 0 0" />
    <limit
      lower="91"
      upper="261"
      effort="10"
      velocity="10" />
  </joint>
  <link
    name="link3">
    <inertial>
      <origin
        xyz="-0.0558954894050296 0.0364989301028535 -3.88490223929699E-05"
        rpy="0 0 0" />
      <mass
        value="0.116258512036894" />
      <inertia
        ixx="3.35800033417872E-05"
        ixy="7.92385750859477E-21"
        ixz="-1.18222483832458E-08"
        iyy="0.000272466308939355"
        iyz="1.65251130604534E-21"
        izz="0.000275237654258283" />
    </inertial>
    <visual>
      <origin
        xyz="0 0 0"
        rpy="0 0 0" />
      <geometry>
        <mesh
          filename="package://Assem3/meshes/link3.STL" />
      </geometry>
      <material
        name="">
        <color
          rgba="0.792156862745098 0.819607843137255 0.933333333333333 1" />
      </material>
    </visual>
    <collision>
      <origin
        xyz="0 0 0"
        rpy="0 0 0" />
      <geometry>
        <mesh
          filename="package://Assem3/meshes/link3.STL" />
      </geometry>
    </collision>
  </link>
  <joint
    name="link2_link3"
    type="revolute">
    <origin
      xyz="-0.2 0.0415 0"
      rpy="0 0.18979 0" />
    <parent
      link="link2" />
    <child
      link="link3" />
    <axis
      xyz="0 1 0" />
    <limit
      lower="-2.182"
      upper="2.182"
      effort="10"
      velocity="10" />
  </joint>
  <link
    name="link4">
    <inertial>
      <origin
        xyz="2.10630237170717E-05 0.0121299634525578 2.13453470453429E-05"
        rpy="0 0 0" />
      <mass
        value="0.0448303181726018" />
      <inertia
        ixx="6.70288197367604E-06"
        ixy="-6.38671062989326E-09"
        ixz="1.61166740925756E-10"
        iyy="9.1784910924838E-06"
        iyz="-6.45769090371768E-09"
        izz="6.70286252196424E-06" />
    </inertial>
    <visual>
      <origin
        xyz="0 0 0"
        rpy="0 0 0" />
      <geometry>
        <mesh
          filename="package://Assem3/meshes/link4.STL" />
      </geometry>
      <material
        name="">
        <color
          rgba="0.792156862745098 0.819607843137255 0.933333333333333 1" />
      </material>
    </visual>
    <collision>
      <origin
        xyz="0 0 0"
        rpy="0 0 0" />
      <geometry>
        <mesh
          filename="package://Assem3/meshes/link4.STL" />
      </geometry>
    </collision>
  </link>
  <joint
    name="link3_link4"
    type="continuous">
    <origin
      xyz="-0.15 0 0"
      rpy="3.1416 -0.90238 3.1416" />
    <parent
      link="link3" />
    <child
      link="link4" />
    <axis
      xyz="0 1 0" />
  </joint>
</robot>